<?xml version="1.0" encoding="UTF-8"?>
<testsuite name="principal.MainTest" tests="8" skipped="0" failures="6" errors="0" timestamp="2020-12-14T13:33:48" hostname="A121-PC04" time="0.121">
  <properties/>
  <testcase name="test01CreacionArray" classname="principal.MainTest" time="0.011"/>
  <testcase name="test02PoblarArray" classname="principal.MainTest" time="0.034"/>
  <testcase name="test03OrdenarArray" classname="principal.MainTest" time="0.005">
    <failure message="java.lang.AssertionError: expected not same" type="java.lang.AssertionError">java.lang.AssertionError: expected not same
	at org.junit.Assert.fail(Assert.java:88)
	at org.junit.Assert.failSame(Assert.java:819)
	at org.junit.Assert.assertNotSame(Assert.java:798)
	at org.junit.Assert.assertNotSame(Assert.java:811)
	at principal.MainTest.test03OrdenarArray(MainTest.java:81)
	at java.base/jdk.internal.reflect.NativeMethodAccessorImpl.invoke0(Native Method)
	at java.base/jdk.internal.reflect.NativeMethodAccessorImpl.invoke(NativeMethodAccessorImpl.java:62)
	at java.base/jdk.internal.reflect.DelegatingMethodAccessorImpl.invoke(DelegatingMethodAccessorImpl.java:43)
	at java.base/java.lang.reflect.Method.invoke(Method.java:564)
	at org.junit.runners.model.FrameworkMethod$1.runReflectiveCall(FrameworkMethod.java:50)
	at org.junit.internal.runners.model.ReflectiveCallable.run(ReflectiveCallable.java:12)
	at org.junit.runners.model.FrameworkMethod.invokeExplosively(FrameworkMethod.java:47)
	at org.junit.internal.runners.statements.InvokeMethod.evaluate(InvokeMethod.java:17)
	at org.junit.internal.runners.statements.RunBefores.evaluate(RunBefores.java:26)
	at org.junit.internal.runners.statements.RunAfters.evaluate(RunAfters.java:27)
	at org.junit.internal.runners.statements.FailOnTimeout$CallableStatement.call(FailOnTimeout.java:298)
	at org.junit.internal.runners.statements.FailOnTimeout$CallableStatement.call(FailOnTimeout.java:292)
	at java.base/java.util.concurrent.FutureTask.run(FutureTask.java:264)
	at java.base/java.lang.Thread.run(Thread.java:832)
</failure>
  </testcase>
  <testcase name="test04ImprimirArray" classname="principal.MainTest" time="0.016">
    <failure message="org.junit.ComparisonFailure: expected:&lt;[][1,2,3]&gt; but was:&lt;[array=][1,2,3]&gt;" type="org.junit.ComparisonFailure">org.junit.ComparisonFailure: expected:&lt;[][1,2,3]&gt; but was:&lt;[array=][1,2,3]&gt;
	at org.junit.Assert.assertEquals(Assert.java:115)
	at org.junit.Assert.assertEquals(Assert.java:144)
	at principal.MainTest.test04ImprimirArray(MainTest.java:96)
	at java.base/jdk.internal.reflect.NativeMethodAccessorImpl.invoke0(Native Method)
	at java.base/jdk.internal.reflect.NativeMethodAccessorImpl.invoke(NativeMethodAccessorImpl.java:62)
	at java.base/jdk.internal.reflect.DelegatingMethodAccessorImpl.invoke(DelegatingMethodAccessorImpl.java:43)
	at java.base/java.lang.reflect.Method.invoke(Method.java:564)
	at org.junit.runners.model.FrameworkMethod$1.runReflectiveCall(FrameworkMethod.java:50)
	at org.junit.internal.runners.model.ReflectiveCallable.run(ReflectiveCallable.java:12)
	at org.junit.runners.model.FrameworkMethod.invokeExplosively(FrameworkMethod.java:47)
	at org.junit.internal.runners.statements.InvokeMethod.evaluate(InvokeMethod.java:17)
	at org.junit.internal.runners.statements.RunBefores.evaluate(RunBefores.java:26)
	at org.junit.internal.runners.statements.RunAfters.evaluate(RunAfters.java:27)
	at org.junit.internal.runners.statements.FailOnTimeout$CallableStatement.call(FailOnTimeout.java:298)
	at org.junit.internal.runners.statements.FailOnTimeout$CallableStatement.call(FailOnTimeout.java:292)
	at java.base/java.util.concurrent.FutureTask.run(FutureTask.java:264)
	at java.base/java.lang.Thread.run(Thread.java:832)
</failure>
  </testcase>
  <testcase name="test05MainBasico" classname="principal.MainTest" time="0.027">
    <failure message="java.lang.AssertionError" type="java.lang.AssertionError">java.lang.AssertionError
	at org.junit.Assert.fail(Assert.java:86)
	at org.junit.Assert.assertTrue(Assert.java:41)
	at org.junit.Assert.assertTrue(Assert.java:52)
	at principal.MainTest.test05MainBasico(MainTest.java:134)
	at java.base/jdk.internal.reflect.NativeMethodAccessorImpl.invoke0(Native Method)
	at java.base/jdk.internal.reflect.NativeMethodAccessorImpl.invoke(NativeMethodAccessorImpl.java:62)
	at java.base/jdk.internal.reflect.DelegatingMethodAccessorImpl.invoke(DelegatingMethodAccessorImpl.java:43)
	at java.base/java.lang.reflect.Method.invoke(Method.java:564)
	at org.junit.runners.model.FrameworkMethod$1.runReflectiveCall(FrameworkMethod.java:50)
	at org.junit.internal.runners.model.ReflectiveCallable.run(ReflectiveCallable.java:12)
	at org.junit.runners.model.FrameworkMethod.invokeExplosively(FrameworkMethod.java:47)
	at org.junit.internal.runners.statements.InvokeMethod.evaluate(InvokeMethod.java:17)
	at org.junit.internal.runners.statements.RunBefores.evaluate(RunBefores.java:26)
	at org.junit.internal.runners.statements.RunAfters.evaluate(RunAfters.java:27)
	at org.junit.internal.runners.statements.FailOnTimeout$CallableStatement.call(FailOnTimeout.java:298)
	at org.junit.internal.runners.statements.FailOnTimeout$CallableStatement.call(FailOnTimeout.java:292)
	at java.base/java.util.concurrent.FutureTask.run(FutureTask.java:264)
	at java.base/java.lang.Thread.run(Thread.java:832)
</failure>
  </testcase>
  <testcase name="test06erroresCreacionArray" classname="principal.MainTest" time="0.007">
    <failure message="java.lang.NegativeArraySizeException: -1" type="java.lang.NegativeArraySizeException">java.lang.NegativeArraySizeException: -1
	at principal.Main.creaArray(Main.java:67)
	at principal.MainTest.test06erroresCreacionArray(MainTest.java:149)
	at java.base/jdk.internal.reflect.NativeMethodAccessorImpl.invoke0(Native Method)
	at java.base/jdk.internal.reflect.NativeMethodAccessorImpl.invoke(NativeMethodAccessorImpl.java:62)
	at java.base/jdk.internal.reflect.DelegatingMethodAccessorImpl.invoke(DelegatingMethodAccessorImpl.java:43)
	at java.base/java.lang.reflect.Method.invoke(Method.java:564)
	at org.junit.runners.model.FrameworkMethod$1.runReflectiveCall(FrameworkMethod.java:50)
	at org.junit.internal.runners.model.ReflectiveCallable.run(ReflectiveCallable.java:12)
	at org.junit.runners.model.FrameworkMethod.invokeExplosively(FrameworkMethod.java:47)
	at org.junit.internal.runners.statements.InvokeMethod.evaluate(InvokeMethod.java:17)
	at org.junit.internal.runners.statements.RunBefores.evaluate(RunBefores.java:26)
	at org.junit.internal.runners.statements.RunAfters.evaluate(RunAfters.java:27)
	at org.junit.internal.runners.statements.FailOnTimeout$CallableStatement.call(FailOnTimeout.java:298)
	at org.junit.internal.runners.statements.FailOnTimeout$CallableStatement.call(FailOnTimeout.java:292)
	at java.base/java.util.concurrent.FutureTask.run(FutureTask.java:264)
	at java.base/java.lang.Thread.run(Thread.java:832)
</failure>
  </testcase>
  <testcase name="test07erroresPoblacionArray" classname="principal.MainTest" time="0.005">
    <failure message="java.util.InputMismatchException" type="java.util.InputMismatchException">java.util.InputMismatchException
	at java.base/java.util.Scanner.throwFor(Scanner.java:939)
	at java.base/java.util.Scanner.next(Scanner.java:1594)
	at java.base/java.util.Scanner.nextInt(Scanner.java:2258)
	at java.base/java.util.Scanner.nextInt(Scanner.java:2212)
	at principal.Main.poblarArray(Main.java:95)
	at principal.MainTest.test07erroresPoblacionArray(MainTest.java:180)
	at java.base/jdk.internal.reflect.NativeMethodAccessorImpl.invoke0(Native Method)
	at java.base/jdk.internal.reflect.NativeMethodAccessorImpl.invoke(NativeMethodAccessorImpl.java:62)
	at java.base/jdk.internal.reflect.DelegatingMethodAccessorImpl.invoke(DelegatingMethodAccessorImpl.java:43)
	at java.base/java.lang.reflect.Method.invoke(Method.java:564)
	at org.junit.runners.model.FrameworkMethod$1.runReflectiveCall(FrameworkMethod.java:50)
	at org.junit.internal.runners.model.ReflectiveCallable.run(ReflectiveCallable.java:12)
	at org.junit.runners.model.FrameworkMethod.invokeExplosively(FrameworkMethod.java:47)
	at org.junit.internal.runners.statements.InvokeMethod.evaluate(InvokeMethod.java:17)
	at org.junit.internal.runners.statements.RunBefores.evaluate(RunBefores.java:26)
	at org.junit.internal.runners.statements.RunAfters.evaluate(RunAfters.java:27)
	at org.junit.internal.runners.statements.FailOnTimeout$CallableStatement.call(FailOnTimeout.java:298)
	at org.junit.internal.runners.statements.FailOnTimeout$CallableStatement.call(FailOnTimeout.java:292)
	at java.base/java.util.concurrent.FutureTask.run(FutureTask.java:264)
	at java.base/java.lang.Thread.run(Thread.java:832)
</failure>
  </testcase>
  <testcase name="test08MainGestionErrores" classname="principal.MainTest" time="0.016">
    <failure message="java.util.InputMismatchException" type="java.util.InputMismatchException">java.util.InputMismatchException
	at java.base/java.util.Scanner.throwFor(Scanner.java:939)
	at java.base/java.util.Scanner.next(Scanner.java:1594)
	at java.base/java.util.Scanner.nextInt(Scanner.java:2258)
	at java.base/java.util.Scanner.nextInt(Scanner.java:2212)
	at principal.Main.creaArray(Main.java:66)
	at principal.Main.main(Main.java:39)
	at principal.MainTest.test08MainGestionErrores(MainTest.java:202)
	at java.base/jdk.internal.reflect.NativeMethodAccessorImpl.invoke0(Native Method)
	at java.base/jdk.internal.reflect.NativeMethodAccessorImpl.invoke(NativeMethodAccessorImpl.java:62)
	at java.base/jdk.internal.reflect.DelegatingMethodAccessorImpl.invoke(DelegatingMethodAccessorImpl.java:43)
	at java.base/java.lang.reflect.Method.invoke(Method.java:564)
	at org.junit.runners.model.FrameworkMethod$1.runReflectiveCall(FrameworkMethod.java:50)
	at org.junit.internal.runners.model.ReflectiveCallable.run(ReflectiveCallable.java:12)
	at org.junit.runners.model.FrameworkMethod.invokeExplosively(FrameworkMethod.java:47)
	at org.junit.internal.runners.statements.InvokeMethod.evaluate(InvokeMethod.java:17)
	at org.junit.internal.runners.statements.RunBefores.evaluate(RunBefores.java:26)
	at org.junit.internal.runners.statements.RunAfters.evaluate(RunAfters.java:27)
	at org.junit.internal.runners.statements.FailOnTimeout$CallableStatement.call(FailOnTimeout.java:298)
	at org.junit.internal.runners.statements.FailOnTimeout$CallableStatement.call(FailOnTimeout.java:292)
	at java.base/java.util.concurrent.FutureTask.run(FutureTask.java:264)
	at java.base/java.lang.Thread.run(Thread.java:832)
</failure>
  </testcase>
  <system-out><![CDATA[]]></system-out>
  <system-err><![CDATA[]]></system-err>
</testsuite>
